Workbook

Sheet Sayfa1
A1: Kod | B1: Son.Fyt | C1: Yön | D1: Al.Fyt | E1: Sat.Fyt | F1: Yks | G1: Dşk | H1: Hcm | I1: Lot | J1: ÖncK | K1: Frk | L1: Frk% | M1: Yks | N1: Dşk | O1: Hcm | P1: Lot | Q1: ÖncK | R1: Frk | S1: Frk% | T1: Açl.Gün
A2: A1CAP | B2: 27,86 | C2: Ç | D2: 27,82 | E2: 27,86 | F2: 28,28 | G2: 27,38 | H2: 30.033.253 | I2: 1.077.426 | J2: 27,48 | K2: 0,38 | L2: 1,38 | M2: 28,28 | N2: 27,38 | O2: 30.033.253 | P2: 1.077.426 | Q2: 27,48 | R2: 0,38 | S2: 1,38 | T2: 27,48
A3: ACSEL | B3: 144,00 | C3: È | D3: 144,00 | E3: 144,20 | F3: 145,40 | G3: 140,20 | H3: 18.915.874 | I3: 131.965 | J3: 140,40 | K3: 3,60 | L3: 2,56 | M3: 145,40 | N3: 140,20 | O3: 18.915.874 | P3: 131.965 | Q3: 140,40 | R3: 3,60 | S3: 2,56 | T3: 140,40
A4: ADEL | B4: 662,00 | C4: È | D4: 662,00 | E4: 663,00 | F4: 671,00 | G4: 648,50 | H4: 160.002.438 | I4: 242.113 | J4: 660,00 | K4: 2,00 | L4: 0,30 | M4: 671,00 | N4: 648,50 | O4: 160.002.438 | P4: 242.113 | Q4: 660,00 | R4: 2,00 | S4: 0,30 | T4: 663,00
A5: ADESE | B5: 2,32 | C5: Ç | D5: 2,31 | E5: 2,32 | F5: 2,34 | G5: 2,27 | H5: 115.315.479 | I5: 50.003.224 | J5: 2,30 | K5: 0,02 | L5: 0,87 | M5: 2,34 | N5: 2,27 | O5: 115.315.479 | P5: 50.003.224 | Q5: 2,30 | R5: 0,02 | S5: 0,87 | T5: 2,31
A6: ADGYO | B6: 25,74 | C6: È | D6: 25,72 | E6: 25,74 | F6: 27,22 | G6: 25,74 | H6: 41.929.646 | I6: 1.578.582 | J6: 27,08 | K6: -1,34 | L6: -4,95 | M6: 27,22 | N6: 25,74 | O6: 41.929.646 | P6: 1.578.582 | Q6: 27,08 | R6: -1,34 | S6: -4,95 | T6: 27,08
A7: AEFES | B7: 214,00 | C7: Ç | D7: 214,00 | E7: 214,10 | F7: 220,90 | G7: 211,80 | H7: 570.936.299 | I7: 2.651.423 | J7: 214,00 | K7: 0,00 | L7: 0,00 | M7: 220,90 | N7: 211,80 | O7: 570.936.299 | P7: 2.651.423 | Q7: 214,00 | R7: 0,00 | S7: 0,00 | T7: 215,00
A8: AFYON | B8: 13,00 | C8: È | D8: 13,00 | E8: 13,02 | F8: 13,13 | G8: 12,90 | H8: 40.922.280 | I8: 3.145.824 | J8: 12,94 | K8: 0,06 | L8: 0,46 | M8: 13,13 | N8: 12,90 | O8: 40.922.280 | P8: 3.145.824 | Q8: 12,94 | R8: 0,06 | S8: 0,46 | T8: 12,94
A9: AGESA | B9: 107,80 | C9: È | D9: 107,60 | E9: 107,80 | F9: 111,00 | G9: 104,40 | H9: 136.698.175 | I9: 1.262.203 | J9: 105,00 | K9: 2,80 | L9: 2,67 | M9: 111,00 | N9: 104,40 | O9: 136.698.175 | P9: 1.262.203 | Q9: 105,00 | R9: 2,80 | S9: 2,67 | T9: 105,00
A10: AGHOL | B10: 360,00 | C10: È | D10: 360,00 | E10: 360,25 | F10: 368,75 | G10: 347,00 | H10: 434.207.932 | I10: 1.218.241 | J10: 357,50 | K10: 2,50 | L10: 0,70 | M10: 368,75 | N10: 347,00 | O10: 434.207.932 | P10: 1.218.241 | Q10: 357,50 | R10: 2,50 | S10: 0,70 | T10: 358,50
A11: AGROT | B11: 17,11 | C11: È | D11: 17,11 | E11: 17,12 | F11: 18,42 | G11: 17,11 | H11: 1.082.571.480 | I11: 61.430.139 | J11: 18,28 | K11: -1,17 | L11: -6,40 | M11: 18,42 | N11: 17,11 | O11: 1.082.571.480 | P11: 61.430.139 | Q11: 18,28 | R11: -1,17 | S11: -6,40 | T11: 18,40
A12: AGYO | B12: 8,63 | C12: Ç | D12: 8,59 | E12: 8,63 | F12: 8,65 | G12: 8,16 | H12: 32.990.935 | I12: 3.909.669 | J12: 8,19 | K12: 0,44 | L12: 5,37 | M12: 8,65 | N12: 8,16 | O12: 32.990.935 | P12: 3.909.669 | Q12: 8,19 | R12: 0,44 | S12: 5,37 | T12: 8,20
A13: AHGAZ | B13: 13,95 | C13: È | D13: 13,94 | E13: 13,95 | F13: 14,11 | G13: 13,90 | H13: 89.562.410 | I13: 6.394.590 | J13: 13,98 | K13: -0,03 | L13: -0,21 | M13: 14,11 | N13: 13,90 | O13: 89.562.410 | P13: 6.394.590 | Q13: 13,98 | R13: -0,03 | S13: -0,21 | T13: 13,95
A14: AKBNK | B14: 63,50 | C14: È | D14: 63,50 | E14: 63,55 | F14: 67,40 | G14: 63,50 | H14: 3.742.795.886 | I14: 57.120.992 | J14: 66,80 | K14: -3,30 | L14: -4,94 | M14: 67,40 | N14: 63,50 | O14: 3.742.795.886 | P14: 57.120.992 | Q14: 66,80 | R14: -3,30 | S14: -4,94 | T14: 66,80
A15: AKCNS | B15: 135,70 | C15: Ç | D15: 135,50 | E15: 135,70 | F15: 138,80 | G15: 133,90 | H15: 89.734.813 | I15: 661.29 | J15: 136,60 | K15: -0,90 | L15: -0,66 | M15: 138,80 | N15: 133,90 | O15: 89.734.813 | P15: 661.29 | Q15: 136,60 | R15: -0,90 | S15: -0,66 | T15: 136,70
A16: AKENR | B16: 16,67 | C16: Ç | D16: 16,67 | F16: 16,67 | G16: 14,97 | H16: 158.701.629 | I16: 9.798.546 | J16: 15,16 | K16: 1,51 | L16: 9,96 | M16: 16,67 | N16: 14,97 | O16: 158.701.629 | P16: 9.798.546 | Q16: 15,16 | R16: 1,51 | S16: 9,96 | T16: 15,18
A17: AKFGY | B17: 2,35 | C17: Ç | D17: 2,34 | E17: 2,35 | F17: 2,41 | G17: 2,30 | H17: 209.744.146 | I17: 89.303.603 | J17: 2,30 | K17: 0,05 | L17: 2,17 | M17: 2,41 | N17: 2,30 | O17: 209.744.146 | P17: 89.303.603 | Q17: 2,30 | R17: 0,05 | S17: 2,17 | T17: 2,30
A18: AKFYE | B18: 27,20 | C18: È | D18: 27,18 | E18: 27,20 | F18: 27,90 | G18: 27,04 | H18: 181.772.574 | I18: 6.630.888 | J18: 27,56 | K18: -0,36 | L18: -1,31 | M18: 27,90 | N18: 27,04 | O18: 181.772.574 | P18: 6.630.888 | Q18: 27,56 | R18: -0,36 | S18: -1,31 | T18: 27,56
A19: AKGRT | B19: 8,03 | C19: È | D19: 8,03 | E19: 8,05 | F19: 8,30 | G19: 7,95 | H19: 241.222.458 | I19: 29.619.896 | J19: 7,95 | K19: 0,08 | L19: 1,01 | M19: 8,30 | N19: 7,95 | O19: 241.222.458 | P19: 29.619.896 | Q19: 7,95 | R19: 0,08 | S19: 1,01 | T19: 7,95
A20: AKMGY | B20: 305,75 | C20: Ç | D20: 304,25 | E20: 305,75 | F20: 311,50 | G20: 299,25 | H20: 18.266.907 | I20: 59.869 | J20: 301,25 | K20: 4,50 | L20: 1,49 | M20: 311,50 | N20: 299,25 | O20: 18.266.907 | P20: 59.869 | Q20: 301,25 | R20: 4,50 | S20: 1,49 | T20: 301,25
A21: AKSA | B21: 123,90 | C21: Ç | D21: 123,80 | E21: 123,90 | F21: 126,00 | G21: 118,80 | H21: 418.701.927 | I21: 3.387.575 | J21: 118,70 | K21: 5,20 | L21: 4,38 | M21: 126,00 | N21: 118,80 | O21: 418.701.927 | P21: 3.387.575 | Q21: 118,70 | R21: 5,20 | S21: 4,38 | T21: 118,80
A22: AKSEN | B22: 46,32 | C22: È | D22: 46,32 | E22: 46,34 | F22: 47,28 | G22: 46,04 | H22: 200.982.145 | I22: 4.300.623 | J22: 46,30 | K22: 0,02 | L22: 0,04 | M22: 47,28 | N22: 46,04 | O22: 200.982.145 | P22: 4.300.623 | Q22: 46,30 | R22: 0,02 | S22: 0,04 | T22: 46,30
A23: AKSGY | B23: 18,00 | C23: È | D23: 17,99 | E23: 18,00 | F23: 18,53 | G23: 17,70 | H23: 51.581.334 | I23: 2.832.718 | J23: 17,70 | K23: 0,30 | L23: 1,69 | M23: 18,53 | N23: 17,70 | O23: 51.581.334 | P23: 2.832.718 | Q23: 17,70 | R23: 0,30 | S23: 1,69 | T23: 17,70
A24: AKSUE | B24: 13,11 | C24: È | D24: 13,11 | E24: 13,23 | F24: 13,34 | G24: 12,41 | H24: 17.077.706 | I24: 1.298.224 | J24: 13,02 | K24: 0,09 | L24: 0,69 | M24: 13,34 | N24: 12,41 | O24: 17.077.706 | P24: 1.298.224 | Q24: 13,02 | R24: 0,09 | S24: 0,69 | T24: 13,05
A25: AKYHO | B25: 7,35 | C25: È | D25: 7,35 | E25: 7,36 | F25: 7,73 | G25: 7,29 | H25: 125.473.707 | I25: 16.894.832 | J25: 7,80 | K25: -0,45 | L25: -5,77 | M25: 7,73 | N25: 7,29 | O25: 125.473.707 | P25: 16.894.832 | Q25: 7,80 | R25: -0,45 | S25: -5,77 | T25: 7,39
A26: ALARK | B26: 121,00 | C26: È | D26: 121,00 | E26: 121,10 | F26: 123,00 | G26: 120,40 | H26: 834.344.026 | I26: 6.850.009 | J26: 120,90 | K26: 0,10 | L26: 0,08 | M26: 123,00 | N26: 120,40 | O26: 834.344.026 | P26: 6.850.009 | Q26: 120,90 | R26: 0,10 | S26: 0,08 | T26: 120,90
A27: ALBRK | B27: 5,82 | C27: Ç | D27: 5,81 | E27: 5,82 | F27: 6,00 | G27: 5,81 | H27: 122.307.904 | I27: 20.860.354 | J27: 5,98 | K27: -0,16 | L27: -2,68 | M27: 6,00 | N27: 5,81 | O27: 122.307.904 | P27: 20.860.354 | Q27: 5,98 | R27: -0,16 | S27: -2,68 | T27: 5,91
A28: ALCAR | B28: 1331,00 | C28: Ç | D28: 1331,00 | F28: 1331,00 | G28: 1211,00 | H28: 114.020.220 | I28: 88.573 | J28: 1210,00 | K28: 121,00 | L28: 10,00 | M28: 1331,00 | N28: 1211,00 | O28: 114.020.220 | P28: 88.573 | Q28: 1210,00 | R28: 121,00 | S28: 10,00 | T28: 1211,00
A29: ALCTL | B29: 106,00 | C29: È | D29: 105,90 | E29: 106,00 | F29: 108,40 | G29: 105,40 | H29: 54.472.305 | I29: 508.401 | J29: 106,80 | K29: -0,80 | L29: -0,75 | M29: 108,40 | N29: 105,40 | O29: 54.472.305 | P29: 508.401 | Q29: 106,80 | R29: -0,80 | S29: -0,75 | T29: 107,80
A30: ALFAS | B30: 72,50 | C30: Ç | D30: 72,45 | E30: 72,50 | F30: 73,50 | G30: 72,15 | H30: 190.198.142 | I30: 2.612.731 | J30: 72,90 | K30: -0,40 | L30: -0,55 | M30: 73,50 | N30: 72,15 | O30: 190.198.142 | P30: 2.612.731 | Q30: 72,90 | R30: -0,40 | S30: -0,55 | T30: 72,65
A31: ALGYO | B31: 42,54 | C31: È | D31: 42,54 | E31: 42,70 | F31: 43,04 | G31: 42,48 | H31: 43.027.454 | I31: 1.006.597 | J31: 42,50 | K31: 0,04 | L31: 0,09 | M31: 43,04 | N31: 42,48 | O31: 43.027.454 | P31: 1.006.597 | Q31: 42,50 | R31: 0,04 | S31: 0,09 | T31: 42,50
A32: ALKA | B32: 28,10 | C32: È | D32: 28,10 | E32: 28,12 | F32: 28,54 | G32: 28,06 | H32: 26.083.349 | I32: 922.923 | J32: 28,20 | K32: -0,10 | L32: -0,35 | M32: 28,54 | N32: 28,06 | O32: 26.083.349 | P32: 922.923 | Q32: 28,20 | R32: -0,10 | S32: -0,35 | T32: 28,22
A33: ALKIM | B33: 36,00 | C33: È | D33: 35,98 | E33: 36,00 | F33: 36,96 | G33: 35,56 | H33: 43.218.710 | I33: 1.190.145 | J33: 36,48 | K33: -0,48 | L33: -1,32 | M33: 36,96 | N33: 35,56 | O33: 43.218.710 | P33: 1.190.145 | Q33: 36,48 | R33: -0,48 | S33: -1,32 | T33: 36,48
A34: ALKLC | B34: 25,26 | D34: 25,26 | F34: 25,26 | G34: 25,26 | H34: 7.570.119 | I34: 299.688 | J34: 22,98 | K34: 2,28 | L34: 9,92 | M34: 25,26 | N34: 25,26 | O34: 7.570.119 | P34: 299.688 | Q34: 22,98 | R34: 2,28 | S34: 9,92 | T34: 25,26
A35: ALMAD | B35: 6,74 | C35: Ç | D35: 6,74 | E35: 6,76 | F35: 6,83 | G35: 6,66 | H35: 13.529.344 | I35: 2.003.311 | J35: 6,67 | K35: 0,07 | L35: 1,05 | M35: 6,83 | N35: 6,66 | O35: 13.529.344 | P35: 2.003.311 | Q35: 6,67 | R35: 0,07 | S35: 1,05 | T35: 6,66
A36: ALTNY | B36: 100,00 | C36: Ç | D36: 99,95 | E36: 100,00 | F36: 105,00 | G36: 91,85 | H36: 1.046.095.038 | I36: 10.503.464 | J36: 96,65 | K36: 3,35 | L36: 3,47 | M36: 105,00 | N36: 91,85 | O36: 1.046.095.038 | P36: 10.503.464 | Q36: 96,65 | R36: 3,35 | S36: 3,47 | T36: 96,65
A37: ALVES | B37: 42,84 | C37: Ç | D37: 42,82 | E37: 42,84 | F37: 43,48 | G37: 41,94 | H37: 136.501.210 | I37: 3.182.941 | J37: 42,06 | K37: 0,78 | L37: 1,85 | M37: 43,48 | N37: 41,94 | O37: 136.501.210 | P37: 3.182.941 | Q37: 42,06 | R37: 0,78 | S37: 1,85 | T37: 42,06
A38: ANELE | B38: 18,63 | C38: È | D38: 18,62 | E38: 18,68 | F38: 18,89 | G38: 18,48 | H38: 9.698.322 | I38: 519.501 | J38: 18,75 | K38: -0,12 | L38: -0,64 | M38: 18,89 | N38: 18,48 | O38: 9.698.322 | P38: 519.501 | Q38: 18,75 | R38: -0,12 | S38: -0,64 | T38: 18,79
A39: ANGEN | B39: 12,20 | C39: Ç | D39: 12,18 | E39: 12,20 | F39: 12,34 | G39: 12,05 | H39: 16.520.486 | I39: 1.353.066 | J39: 12,05 | K39: 0,15 | L39: 1,24 | M39: 12,34 | N39: 12,05 | O39: 16.520.486 | P39: 1.353.066 | Q39: 12,05 | R39: 0,15 | S39: 1,24 | T39: 12,06
A40: ANHYT | B40: 106,20 | C40: È | D40: 106,00 | E40: 106,20 | F40: 106,40 | G40: 97,10 | H40: 408.019.478 | I40: 3.937.519 | J40: 97,00 | K40: 9,20 | L40: 9,48 | M40: 106,40 | N40: 97,10 | O40: 408.019.478 | P40: 3.937.519 | Q40: 97,00 | R40: 9,20 | S40: 9,48 | T40: 97,10
...

Sheet Sayfa3
A3: Güncel Portföy
A4: Kod | B4: Ağırlık | D4: Frk%
B5: 0.0668
A6: BIMAS
A7: 0.43092593 | C7: =VLOOKUP(A6,Sayfa1!$A$1:$B$531,1,0) -> BIMAS | D7: =VLOOKUP(C7,Sayfa1!$A$1:$S$531,14,0) -> 475,00 | E7: =(D7*B5) -> 31.73 | G7: =SUM(E7:E157) -> 138.30509
A8: 475 | D8: =VLOOKUP(A7,Sayfa1!$A$1:$S$531,12,0) -> #N/A
A9: -0.0042 | D9: =VLOOKUP(A8,Sayfa1!$A$1:$S$531,12,0) -> #N/A
B10: 0.061 | D10: =VLOOKUP(A9,Sayfa1!$A$1:$S$531,12,0) -> #N/A
A11: MAVI | D11: =VLOOKUP(A10,Sayfa1!$A$1:$S$531,12,0) -> #N/A
A12: 0.43091435 | D12: =VLOOKUP(A11,Sayfa1!$A$1:$S$531,14,0) -> 96,45 | E12: =(D12*B10) -> 5.88345
A13: 98.45 | D13: =VLOOKUP(A12,Sayfa1!$A$1:$S$531,12,0) -> #N/A
A14: -0.0115 | D14: =VLOOKUP(A13,Sayfa1!$A$1:$S$531,12,0) -> #N/A
B15: 0.053 | D15: =VLOOKUP(A14,Sayfa1!$A$1:$S$531,12,0) -> #N/A
A16: PGSUS | D16: =VLOOKUP(A15,Sayfa1!$A$1:$S$531,12,0) -> #N/A
A17: 0.43092593 | D17: =VLOOKUP(A16,Sayfa1!$A$1:$S$531,14,0) -> 208,30 | E17: =(D17*B15) -> 11.0399
A18: 209 | D18: =VLOOKUP(A17,Sayfa1!$A$1:$S$531,12,0) -> #N/A
A19: -0.0071 | D19: =VLOOKUP(A18,Sayfa1!$A$1:$S$531,12,0) -> #N/A
B20: 0.0492 | D20: =VLOOKUP(A19,Sayfa1!$A$1:$S$531,12,0) -> #N/A
A21: TCELL | D21: =VLOOKUP(A20,Sayfa1!$A$1:$S$531,12,0) -> #N/A
A22: 0.4309375 | D22: =VLOOKUP(A21,Sayfa1!$A$1:$S$531,14,0) -> 99,20 | E22: =(D22*B20) -> 4.88064
A23: 88.45 | D23: =VLOOKUP(A22,Sayfa1!$A$1:$S$531,12,0) -> #N/A
A24: -0.0128 | D24: =VLOOKUP(A23,Sayfa1!$A$1:$S$531,12,0) -> #N/A
B25: 0.0474 | D25: =VLOOKUP(A24,Sayfa1!$A$1:$S$531,12,0) -> #N/A
A26: CCOLA | D26: =VLOOKUP(A25,Sayfa1!$A$1:$S$531,12,0) -> #N/A
A27: 0.43083333 | D27: =VLOOKUP(A26,Sayfa1!$A$1:$S$531,14,0) -> 787,00 | E27: =(D27*B25) -> 37.3038
A28: 788 | D28: =VLOOKUP(A27,Sayfa1!$A$1:$S$531,12,0) -> #N/A
A29: 0.0083 | D29: =VLOOKUP(A28,Sayfa1!$A$1:$S$531,12,0) -> #N/A
B30: 0.0471 | D30: =VLOOKUP(A29,Sayfa1!$A$1:$S$531,12,0) -> #N/A
A31: ISCTR | D31: =VLOOKUP(A30,Sayfa1!$A$1:$S$531,12,0) -> #N/A
A32: 0.4309375 | D32: =VLOOKUP(A31,Sayfa1!$A$1:$S$531,14,0) -> 15,91 | E32: =(D32*B30) -> 0.749361
A33: 15.68 | D33: =VLOOKUP(A32,Sayfa1!$A$1:$S$531,12,0) -> #N/A
A34: 0.0006 | D34: =VLOOKUP(A33,Sayfa1!$A$1:$S$531,12,0) -> #N/A
B35: 0.0471 | D35: =VLOOKUP(A34,Sayfa1!$A$1:$S$531,12,0) -> #N/A
A36: SOKM | D36: =VLOOKUP(A35,Sayfa1!$A$1:$S$531,12,0) -> #N/A
A37: 0.43086806 | D37: =VLOOKUP(A36,Sayfa1!$A$1:$S$531,14,0) -> 60,00 | E37: =(D37*B35) -> 2.826
A38: 65.25 | D38: =VLOOKUP(A37,Sayfa1!$A$1:$S$531,12,0) -> #N/A
A39: -0.0031 | D39: =VLOOKUP(A38,Sayfa1!$A$1:$S$531,12,0) -> #N/A
B40: 0.0463 | D40: =VLOOKUP(A39,Sayfa1!$A$1:$S$531,14,0) -> #N/A
A41: AGHOL | D41: =VLOOKUP(A41,Sayfa1!$A$1:$S$531,12,0) -> 0,70
A42: 0.4308912 | D42: =VLOOKUP(A41,Sayfa1!$A$1:$S$531,14,0) -> 347,00 | E42: =(D42*B40) -> 16.0661
...

Sheet Sayfa4
A1: Alış Tarihi | B1: Satış Tarihi | C1: Hisse | D1: Alış Fiyat | E1: Satış Fiyat | F1: Kar | G1: Ağırlık | H1: Ağırlıklı Kar | J1: Günlük Kar | N1: Alış Tarihi | O1: Satış Tarihi | P1: Hisse | Q1: Alış Fiyat | R1: Satış Fiyat | S1: Kar | T1: Ağırlık | U1: Ağırlıklı Kar | W1: Günlük Kar
A2: 45446 | B2: 45448 | C2: GARAN | D2: 108.6 | E2: =VLOOKUP(C2,Sayfa1!A1:T534,2,0) -> 104,30 | F2: =(E2/D2)-1 -> -0.039594843 | G2: 0.3938 | H2: =PRODUCT(G2,F2) -> -0.015592449 | J2: =SUM(H2:H3) -> -0.011074188 | N2: 45446 | O2: 45448 | P2: GARAN | Q2: 108.6 | R2: =VLOOKUP(C2,Sayfa1!A1:T534,2,0) -> 104,30 | S2: =(R2/Q2)-1 -> -0.039594843 | T2: 0.2968 | U2: =PRODUCT(T2,S2) -> -0.01175175 | W2: =SUM(U2:U4) -> 0.0012273388
C3: TURSG | D3: 80.5 | E3: =VLOOKUP(C3,Sayfa1!A1:T534,2,0) -> 81,10 | F3: =(E3/D3)-1 -> 0.0074534161 | G3: 0.6062 | H3: =PRODUCT(G3,F3) -> 0.0045182609 | P3: TURSG | Q3: 80.5 | R3: =VLOOKUP(P3,Sayfa1!A1:T534,2,0) -> 81,10 | S3: =(R3/Q3)-1 -> 0.0074534161 | T3: 0.4382 | U3: =PRODUCT(T3,S3) -> 0.003266087
P4: ULKER | Q4: 144.6 | R4: =VLOOKUP(P4,Sayfa1!A1:T534,2,0) -> 149,90 | S4: =(R4/Q4)-1 -> 0.036652835 | T4: 0.265 | U4: =PRODUCT(T4,S4) -> 0.0097130014
